{
    "containers": {
        "cna": {
            "affected": [
                {
                    "defaultStatus": "unknown",
                    "product": "Community Collections",
                    "vendor": "AWS Community",
                    "versions": [
                        {
                            "status": "affected",
                            "version": "from 1.0.0 to 1.2.0"
                        }
                    ]
                }
            ],
            "descriptions": [
                {
                    "lang": "en",
                    "value": "A flaw was found in Ansible Base when using the aws_ssm connection plugin as garbage collector is not happening after playbook run is completed. Files would remain in the bucket exposing the data. This issue affects directly data confidentiality."
                }
            ],
            "metrics": [
                {
                    "cvssV3_0": {
                        "vectorString": "5/CVSS:3.1/AV:L/AC:L/PR:L/UI:R/S:U/C:H/I:N/A:N",
                        "version": "3.0"
                    }
                }
            ],
            "problemTypes": [
                {
                    "descriptions": [
                        {
                            "cweId": "CWE-212",
                            "description": "CWE-212",
                            "lang": "en",
                            "type": "CWE"
                        }
                    ]
                }
            ],
            "providerMetadata": {
                "dateUpdated": "2022-01-13T00:00:00",
                "orgId": "53f830b8-0a3f-465b-8143-3b8a9948e749",
                "shortName": "redhat"
            },
            "references": [
                {
                    "name": "https://github.com/ansible-collections/community.aws/issues/222",
                    "url": "https://github.com/ansible-collections/community.aws/issues/222",
                    "x_refsource": "MISC"
                },
                {
                    "name": "https://bugzilla.redhat.com/show_bug.cgi?id=CVE-2020-25635",
                    "url": "https://bugzilla.redhat.com/show_bug.cgi?id=CVE-2020-25635",
                    "x_refsource": "CONFIRM"
                }
            ],
            "x_legacyV4Record": {
                "CVE_data_meta": {
                    "ASSIGNER": "secalert@redhat.com",
                    "ID": "CVE-2020-25635",
                    "STATE": "PUBLIC"
                },
                "affects": {
                    "vendor": {
                        "vendor_data": [
                            {
                                "product": {
                                    "product_data": [
                                        {
                                            "product_name": "Community Collections",
                                            "version": {
                                                "version_data": [
                                                    {
                                                        "version_value": "from 1.0.0 to 1.2.0"
                                                    }
                                                ]
                                            }
                                        }
                                    ]
                                },
                                "vendor_name": "AWS Community"
                            }
                        ]
                    }
                },
                "data_format": "MITRE",
                "data_type": "CVE",
                "data_version": "4.0",
                "description": {
                    "description_data": [
                        {
                            "lang": "eng",
                            "value": "A flaw was found in Ansible Base when using the aws_ssm connection plugin as garbage collector is not happening after playbook run is completed. Files would remain in the bucket exposing the data. This issue affects directly data confidentiality."
                        }
                    ]
                },
                "impact": {
                    "cvss": [
                        [
                            {
                                "vectorString": "5/CVSS:3.1/AV:L/AC:L/PR:L/UI:R/S:U/C:H/I:N/A:N",
                                "version": "3.0"
                            }
                        ]
                    ]
                },
                "problemtype": {
                    "problemtype_data": [
                        {
                            "description": [
                                {
                                    "lang": "eng",
                                    "value": "CWE-212"
                                }
                            ]
                        }
                    ]
                },
                "references": {
                    "reference_data": [
                        {
                            "name": "https://github.com/ansible-collections/community.aws/issues/222",
                            "refsource": "MISC",
                            "url": "https://github.com/ansible-collections/community.aws/issues/222"
                        },
                        {
                            "name": "https://bugzilla.redhat.com/show_bug.cgi?id=CVE-2020-25635",
                            "refsource": "CONFIRM",
                            "url": "https://bugzilla.redhat.com/show_bug.cgi?id=CVE-2020-25635"
                        }
                    ]
                }
            }
        }
    },
    "cveMetadata": {
        "assignerOrgId": "53f830b8-0a3f-465b-8143-3b8a9948e749",
        "assignerShortName": "redhat",
        "cveId": "CVE-2020-25635",
        "dateUpdated": "2022-01-13T00:00:00",
        "state": "PUBLISHED"
    },
    "dataType": "CVE_RECORD",
    "dataVersion": "5.0",
    "x_ValidationErrors": [
        "$ -- validator = oneOf"
    ]
}