{
    "containers": {
        "cna": {
            "affected": [
                {
                    "product": "n/a",
                    "vendor": "n/a",
                    "versions": [
                        {
                            "status": "affected",
                            "version": "n/a",
                            "versionType": "custom"
                        }
                    ]
                }
            ],
            "descriptions": [
                {
                    "lang": "en",
                    "value": "In Python 3.8.4, sys.path restrictions specified in a python38._pth file are ignored, allowing code to be loaded from arbitrary locations. The <executable-name>._pth file (e.g., the python._pth file) is not affected."
                }
            ],
            "problemtypes": [
                {
                    "descriptions": [
                        {
                            "description": "n/a",
                            "lang": "en",
                            "type": "text"
                        }
                    ]
                }
            ],
            "providerMetadata": {
                "dateUpdated": "2021-12-15",
                "orgId": "8254265b-2729-46b6-b9e3-3dfca2d5bfca",
                "shortName": "mitre"
            },
            "references": [
                {
                    "name": "https://bugs.python.org/issue41304",
                    "url": "https://bugs.python.org/issue41304"
                },
                {
                    "name": "https://github.com/python/cpython/pull/21495",
                    "url": "https://github.com/python/cpython/pull/21495"
                },
                {
                    "name": "https://security.netapp.com/advisory/ntap-20200731-0003/",
                    "url": "https://security.netapp.com/advisory/ntap-20200731-0003/"
                }
            ],
            "x_legacyV4Record": {
                "CVE_data_meta": {
                    "ASSIGNER": "cve@mitre.org",
                    "ID": "CVE-2020-15801",
                    "STATE": "PUBLIC"
                },
                "affects": {
                    "vendor": {
                        "vendor_data": [
                            {
                                "product": {
                                    "product_data": [
                                        {
                                            "product_name": "n/a",
                                            "version": {
                                                "version_data": [
                                                    {
                                                        "version_value": "n/a"
                                                    }
                                                ]
                                            }
                                        }
                                    ]
                                },
                                "vendor_name": "n/a"
                            }
                        ]
                    }
                },
                "data_format": "MITRE",
                "data_type": "CVE",
                "data_version": "4.0",
                "description": {
                    "description_data": [
                        {
                            "lang": "eng",
                            "value": "In Python 3.8.4, sys.path restrictions specified in a python38._pth file are ignored, allowing code to be loaded from arbitrary locations. The <executable-name>._pth file (e.g., the python._pth file) is not affected."
                        }
                    ]
                },
                "problemtype": {
                    "problemtype_data": [
                        {
                            "description": [
                                {
                                    "lang": "eng",
                                    "value": "n/a"
                                }
                            ]
                        }
                    ]
                },
                "references": {
                    "reference_data": [
                        {
                            "name": "https://bugs.python.org/issue41304",
                            "refsource": "MISC",
                            "url": "https://bugs.python.org/issue41304"
                        },
                        {
                            "name": "https://github.com/python/cpython/pull/21495",
                            "refsource": "MISC",
                            "url": "https://github.com/python/cpython/pull/21495"
                        },
                        {
                            "name": "https://security.netapp.com/advisory/ntap-20200731-0003/",
                            "refsource": "CONFIRM",
                            "url": "https://security.netapp.com/advisory/ntap-20200731-0003/"
                        }
                    ]
                }
            }
        }
    },
    "cveMetadata": {
        "assignerOrgId": "8254265b-2729-46b6-b9e3-3dfca2d5bfca",
        "assignerShortName": "mitre",
        "cveId": "CVE-2020-15801",
        "dateUpdated": "2021-12-15",
        "state": "PUBLIC"
    },
    "dataType": "CVE_RECORD",
    "dataVersion": "5.0"
}