{
    "containers": {
        "cna": {
            "affected": [
                {
                    "product": "n/a",
                    "vendor": "n/a",
                    "versions": [
                        {
                            "status": "affected",
                            "version": "n/a",
                            "versionType": "custom"
                        }
                    ]
                }
            ],
            "descriptions": [
                {
                    "lang": "en",
                    "value": "pyshop before 0.7.1 uses HTTP to retrieve packages from the PyPI repository, and does not perform integrity checks on package contents, which allows man-in-the-middle attackers to execute arbitrary code via a crafted response to a download operation."
                }
            ],
            "problemtypes": [
                {
                    "descriptions": [
                        {
                            "description": "n/a",
                            "lang": "en",
                            "type": "text"
                        }
                    ]
                }
            ],
            "providerMetadata": {
                "dateUpdated": "2021-12-15",
                "orgId": "8254265b-2729-46b6-b9e3-3dfca2d5bfca",
                "shortName": "mitre"
            },
            "references": [
                {
                    "name": "https://github.com/mardiros/pyshop/commit/ffadb0bcdef1e385884571670210cfd6ba351784",
                    "url": "https://github.com/mardiros/pyshop/commit/ffadb0bcdef1e385884571670210cfd6ba351784"
                },
                {
                    "name": "https://github.com/mardiros/pyshop/blob/master/CHANGES.txt",
                    "url": "https://github.com/mardiros/pyshop/blob/master/CHANGES.txt"
                },
                {
                    "name": "http://www.reddit.com/r/Python/comments/17rfh7/warning_dont_use_pip_in_an_untrusted_network_a/",
                    "url": "http://www.reddit.com/r/Python/comments/17rfh7/warning_dont_use_pip_in_an_untrusted_network_a/"
                }
            ],
            "x_legacyV4Record": {
                "CVE_data_meta": {
                    "ASSIGNER": "cve@mitre.org",
                    "ID": "CVE-2013-1630",
                    "STATE": "PUBLIC"
                },
                "affects": {
                    "vendor": {
                        "vendor_data": [
                            {
                                "product": {
                                    "product_data": [
                                        {
                                            "product_name": "n/a",
                                            "version": {
                                                "version_data": [
                                                    {
                                                        "version_value": "n/a"
                                                    }
                                                ]
                                            }
                                        }
                                    ]
                                },
                                "vendor_name": "n/a"
                            }
                        ]
                    }
                },
                "data_format": "MITRE",
                "data_type": "CVE",
                "data_version": "4.0",
                "description": {
                    "description_data": [
                        {
                            "lang": "eng",
                            "value": "pyshop before 0.7.1 uses HTTP to retrieve packages from the PyPI repository, and does not perform integrity checks on package contents, which allows man-in-the-middle attackers to execute arbitrary code via a crafted response to a download operation."
                        }
                    ]
                },
                "problemtype": {
                    "problemtype_data": [
                        {
                            "description": [
                                {
                                    "lang": "eng",
                                    "value": "n/a"
                                }
                            ]
                        }
                    ]
                },
                "references": {
                    "reference_data": [
                        {
                            "name": "https://github.com/mardiros/pyshop/commit/ffadb0bcdef1e385884571670210cfd6ba351784",
                            "refsource": "CONFIRM",
                            "url": "https://github.com/mardiros/pyshop/commit/ffadb0bcdef1e385884571670210cfd6ba351784"
                        },
                        {
                            "name": "https://github.com/mardiros/pyshop/blob/master/CHANGES.txt",
                            "refsource": "CONFIRM",
                            "url": "https://github.com/mardiros/pyshop/blob/master/CHANGES.txt"
                        },
                        {
                            "name": "http://www.reddit.com/r/Python/comments/17rfh7/warning_dont_use_pip_in_an_untrusted_network_a/",
                            "refsource": "MISC",
                            "url": "http://www.reddit.com/r/Python/comments/17rfh7/warning_dont_use_pip_in_an_untrusted_network_a/"
                        }
                    ]
                }
            }
        }
    },
    "cveMetadata": {
        "assignerOrgId": "8254265b-2729-46b6-b9e3-3dfca2d5bfca",
        "assignerShortName": "mitre",
        "cveId": "CVE-2013-1630",
        "dateUpdated": "2021-12-15",
        "state": "PUBLIC"
    },
    "dataType": "CVE_RECORD",
    "dataVersion": "5.0"
}